Traceback (most recent call last):
  File "E:\dev\wPCC_pipeline\venv\lib\site-packages\jupyter_cache\executors\utils.py", line 56, in single_nb_execution
    record_timing=False,
  File "E:\dev\wPCC_pipeline\venv\lib\site-packages\nbclient\client.py", line 1093, in execute
    return NotebookClient(nb=nb, resources=resources, km=km, **kwargs).execute()
  File "E:\dev\wPCC_pipeline\venv\lib\site-packages\nbclient\util.py", line 84, in wrapped
    return just_run(coro(*args, **kwargs))
  File "E:\dev\wPCC_pipeline\venv\lib\site-packages\nbclient\util.py", line 62, in just_run
    return loop.run_until_complete(coro)
  File "C:\Python37-64\lib\asyncio\base_events.py", line 587, in run_until_complete
    return future.result()
  File "E:\dev\wPCC_pipeline\venv\lib\site-packages\nbclient\client.py", line 560, in async_execute
    cell, index, execution_count=self.code_cells_executed + 1
  File "E:\dev\wPCC_pipeline\venv\lib\site-packages\nbclient\client.py", line 854, in async_execute_cell
    self._check_raise_for_error(cell, exec_reply)
  File "E:\dev\wPCC_pipeline\venv\lib\site-packages\nbclient\client.py", line 756, in _check_raise_for_error
    raise CellExecutionError.from_cell_and_msg(cell, exec_reply_content)
nbclient.exceptions.CellExecutionError: An error occurred while executing the following cell:
------------------
%load_ext autoreload
%autoreload 2

import pandas as pd
import numpy as np
import matplotlib.pyplot as plt
from numpy.linalg import inv
import sympy as sp

import src.visualization.book_format as book_format
book_format.set_style()
from src.substitute_dynamic_symbols import lambdify
from sympy import Matrix
from sympy.physics.mechanics import (dynamicsymbols, ReferenceFrame,
                                      Particle, Point)
from IPython.display import display, Math, Latex
from src.substitute_dynamic_symbols import run, lambdify
from sympy.physics.vector.printing import vpprint, vlatex
from src.data import mdl
------------------

[1;31m---------------------------------------------------------------------------[0m
[1;31mUnboundLocalError[0m                         Traceback (most recent call last)
[1;32m~\AppData\Local\Temp/ipykernel_18188/3513609185.py[0m in [0;36m<module>[1;34m[0m
[0;32m      8[0m [1;32mimport[0m [0msympy[0m [1;32mas[0m [0msp[0m[1;33m[0m[1;33m[0m[0m
[0;32m      9[0m [1;33m[0m[0m
[1;32m---> 10[1;33m [1;32mimport[0m [0msrc[0m[1;33m.[0m[0mvisualization[0m[1;33m.[0m[0mbook_format[0m [1;32mas[0m [0mbook_format[0m[1;33m[0m[1;33m[0m[0m
[0m[0;32m     11[0m [0mbook_format[0m[1;33m.[0m[0mset_style[0m[1;33m([0m[1;33m)[0m[1;33m[0m[1;33m[0m[0m
[0;32m     12[0m [1;32mfrom[0m [0msrc[0m[1;33m.[0m[0msubstitute_dynamic_symbols[0m [1;32mimport[0m [0mlambdify[0m[1;33m[0m[1;33m[0m[0m

[1;32me:\dev\wpcc\src\visualization\book_format.py[0m in [0;36m<module>[1;34m[0m
[0;32m     96[0m [1;31m# called when this module is imported at the top of each book[0m[1;33m[0m[1;33m[0m[1;33m[0m[0m
[0;32m     97[0m [1;31m# chapter so the reader can see that they need to update their environment.[0m[1;33m[0m[1;33m[0m[1;33m[0m[0m
[1;32m---> 98[1;33m [0mtest_installation[0m[1;33m([0m[1;33m)[0m[1;33m[0m[1;33m[0m[0m
[0m[0;32m     99[0m [1;33m[0m[0m
[0;32m    100[0m [1;33m[0m[0m

[1;32me:\dev\wpcc\src\visualization\book_format.py[0m in [0;36mtest_installation[1;34m()[0m
[0;32m     63[0m     [1;32mfrom[0m [0mdistutils[0m[1;33m.[0m[0mversion[0m [1;32mimport[0m [0mLooseVersion[0m[1;33m[0m[1;33m[0m[0m
[0;32m     64[0m [1;33m[0m[0m
[1;32m---> 65[1;33m     [0mv[0m [1;33m=[0m [0mfilterpy[0m[1;33m.[0m[0m__version__[0m[1;33m[0m[1;33m[0m[0m
[0m[0;32m     66[0m     [0mmin_version[0m [1;33m=[0m [1;34m"1.4.4"[0m[1;33m[0m[1;33m[0m[0m
[0;32m     67[0m     [1;32mif[0m [0mLooseVersion[0m[1;33m([0m[0mv[0m[1;33m)[0m [1;33m<[0m [0mLooseVersion[0m[1;33m([0m[0mmin_version[0m[1;33m)[0m[1;33m:[0m[1;33m[0m[1;33m[0m[0m

[1;31mUnboundLocalError[0m: local variable 'filterpy' referenced before assignment
UnboundLocalError: local variable 'filterpy' referenced before assignment

